<?xml version="1.0"?>
<robot xmlns:xacro="http://www.ros.org/wiki/xacro" name="my_robot">

  <xacro:property name="body_length" value="0.4"/>
  <xacro:property name="body_width" value="0.3"/>
  <xacro:property name="body_height" value="0.15"/>
  <xacro:property name="wheel_radius" value="0.05"/>
  <xacro:property name="wheel_width" value="0.03"/>
  <xacro:property name="caster_radius" value="0.03"/>

  <xacro:macro name="wheel_link" params="name prefix x y z">
    <link name="${prefix}_${name}_wheel">
      <visual>
        <geometry>
          <cylinder radius="${wheel_radius}" length="${wheel_width}"/>
        </geometry>
        <origin xyz="0 0 0" rpy="${pi/2} 0 0"/>
        <material name="black">
          <color rgba="0.2 0.2 0.2 1.0"/>
        </material>
      </visual>
      <collision>
        <geometry>
          <cylinder radius="${wheel_radius}" length="${wheel_width}"/>
        </geometry>
        <origin xyz="0 0 0" rpy="${pi/2} 0 0"/>
      </collision>
      <inertial>
        <mass value="0.2"/>
        <inertia ixx="0.0001" ixy="0.0" ixz="0.0" iyy="0.0001" iyz="0.0" izz="0.0001"/>
      </inertial>
    </link>
    <joint name="${prefix}_${name}_wheel_joint" type="continuous">
      <parent link="base_link"/>
      <child link="${prefix}_${name}_wheel"/>
      <origin xyz="${x} ${y} ${z}" rpy="0 0 0"/>
      <axis xyz="0 1 0"/>
    </joint>
  </xacro:macro>

  <xacro:macro name="caster_link" params="name prefix x y z">
    <link name="${prefix}_${name}_caster">
      <visual>
        <geometry>
          <sphere radius="${caster_radius}"/>
        </geometry>
        <material name="gray">
          <color rgba="0.5 0.5 0.5 1.0"/>
        </material>
      </visual>
      <collision>
        <geometry>
          <sphere radius="${caster_radius}"/>
        </geometry>
      </collision>
      <inertial>
        <mass value="0.05"/>
        <inertia ixx="0.00001" ixy="0.0" ixz="0.0" iyy="0.00001" iyz="0.0" izz="0.00001"/>
      </inertial>
    </link>
    <joint name="${prefix}_${name}_caster_joint" type="fixed">
      <parent link="base_link"/>
      <child link="${prefix}_${name}_caster"/>
      <origin xyz="${x} ${y} ${z}" rpy="0 0 0"/>
    </joint>
  </xacro:macro>

  <link name="base_footprint"/>

  <joint name="base_joint" type="fixed">
    <parent link="base_footprint"/>
    <child link="base_link"/>
    <origin xyz="0 0 0.1" rpy="0 0 0"/>
  </joint>

  <link name="base_link">
    <visual>
      <geometry>
        <box size="${body_length} ${body_width} ${body_height}"/>
      </geometry>
      <origin xyz="0 0 0" rpy="0 0 0"/>
      <material name="blue">
        <color rgba="0.2 0.4 0.8 1.0"/>
      </material>
    </visual>
    <collision>
      <geometry>
        <box size="${body_length} ${body_width} ${body_height}"/>
      </geometry>
      <origin xyz="0 0 0" rpy="0 0 0"/>
    </collision>
    <inertial>
      <mass value="2.0"/>
      <inertia ixx="0.02" ixy="0.0" ixz="0.0" iyy="0.02" iyz="0.0" izz="0.02"/>
    </inertial>
  </link>

  <xacro:wheel_link name="left" prefix="base" x="0.0" y="${body_width/2 + 0.01}" z="${-body_height/2 + wheel_radius}"/>
  <xacro:wheel_link name="right" prefix="base" x="0.0" y="${-body_width/2 - 0.01}" z="${-body_height/2 + wheel_radius}"/>

  <xacro:caster_link name="front" prefix="base" x="${body_length/2 - 0.06}" y="0.0" z="${-body_height/2 + caster_radius - 0.01}"/>
  <xacro:caster_link name="rear" prefix="base" x="${-body_length/2 + 0.06}" y="0.0" z="${-body_height/2 + caster_radius - 0.01}"/>

  <link name="lidar_link">
    <visual>
      <geometry>
        <cylinder radius="0.04" length="0.04"/>
      </geometry>
      <origin xyz="0 0 0" rpy="0 0 0"/>
      <material name="red">
        <color rgba="1.0 0.2 0.2 1.0"/>
      </material>
    </visual>
    <collision>
      <geometry>
        <cylinder radius="0.04" length="0.04"/>
      </geometry>
      <origin xyz="0 0 0" rpy="0 0 0"/>
    </collision>
    <inertial>
      <mass value="0.1"/>
      <inertia ixx="0.0001" ixy="0.0" ixz="0.0" iyy="0.0001" iyz="0.0" izz="0.0001"/>
    </inertial>
  </link>

  <joint name="lidar_joint" type="fixed">
    <parent link="base_link"/>
    <child link="lidar_link"/>
    <origin xyz="0 0 ${body_height/2 + 0.04}" rpy="0 0 0"/>
  </joint>


</robot>
