<?xml version="1.0" ?>
<sdf version="1.6">
  <model name="custom_robot">

    <link name="base_footprint"/>

    <joint name="base_joint" type="fixed">
      <parent>base_footprint</parent>
      <child>base_link</child>
      <pose>0 0 0.125 0 0 0</pose>
    </joint>

    <link name="base_link">
      <inertial>
        <mass>2.0</mass>
        <pose>0 0 0 0 0 0</pose>
        <inertia>
          <ixx>0.03</ixx><ixy>0</ixy><ixz>0</ixz>
          <iyy>0.03</iyy><iyz>0</iyz>
          <izz>0.025</izz>
        </inertia>
      </inertial>
      <collision name="base_collision">
        <geometry><box><size>0.4 0.3 0.15</size></box></geometry>
        <surface><friction><ode><mu>0.8</mu><mu2>0.8</mu2></ode></friction></surface>
      </collision>
      <visual name="base_visual">
        <geometry><box><size>0.4 0.3 0.15</size></box></geometry>
        <material>
          <ambient>0 0 0.8 1</ambient>
          <diffuse>0 0 0.8 1</diffuse>
          <specular>0.1 0.1 0.1 1</specular>
        </material>
      </visual>
    </link>

    <link name="wheel_left_link">
      <inertial>
        <mass>0.1</mass>
        <inertia>
          <ixx>6.6e-5</ixx><ixy>0</ixy><ixz>0</ixz>
          <iyy>6.6e-5</iyy><iyz>0</iyz>
          <izz>1.25e-4</izz>
        </inertia>
      </inertial>
      <collision name="collision">
        <geometry><cylinder><radius>0.05</radius><length>0.02</length></cylinder></geometry>
        <surface><friction><ode><mu>1.0</mu><mu2>1.0</mu2></ode></friction></surface>
      </collision>
      <visual name="visual">
        <geometry><cylinder><radius>0.05</radius><length>0.02</length></cylinder></geometry>
        <material><ambient>0.1 0.1 0.1 1</ambient><diffuse>0.1 0.1 0.1 1</diffuse></material>
      </visual>
    </link>

    <joint name="wheel_left_joint" type="revolute">
      <parent>base_link</parent>
      <child>wheel_left_link</child>
      <axis><xyz>0 1 0</xyz>
        <limit><lower>-1e16</lower><upper>1e16</upper></limit>
        <dynamics><damping>0.1</damping><friction>0.01</friction></dynamics>
      </axis>
      <pose>0 0.18 -0.075 0 0 0</pose>
    </joint>

    <link name="wheel_right_link">
      <inertial>
        <mass>0.1</mass>
        <inertia>
          <ixx>6.6e-5</ixx><ixy>0</ixy><ixz>0</ixz>
          <iyy>6.6e-5</iyy><iyz>0</iyz>
          <izz>1.25e-4</izz>
        </inertia>
      </inertial>
      <collision name="collision">
        <geometry><cylinder><radius>0.05</radius><length>0.02</length></cylinder></geometry>
        <surface><friction><ode><mu>1.0</mu><mu2>1.0</mu2></ode></friction></surface>
      </collision>
      <visual name="visual">
        <geometry><cylinder><radius>0.05</radius><length>0.02</length></cylinder></geometry>
        <material><ambient>0.1 0.1 0.1 1</ambient></material>
      </visual>
    </link>

    <joint name="wheel_right_joint" type="revolute">
      <parent>base_link</parent>
      <child>wheel_right_link</child>
      <axis><xyz>0 1 0</xyz>
        <limit><lower>-1e16</lower><upper>1e16</upper></limit>
        <dynamics><damping>0.1</damping><friction>0.01</friction></dynamics>
      </axis>
      <pose>0 -0.18 -0.075 0 0 0</pose>
    </joint>

    <link name="roller_front_link">
      <inertial>
        <mass>0.03</mass>
        <inertia>
          <ixx>5e-6</ixx><ixy>0</ixy><ixz>0</ixz>
          <iyy>5e-6</iyy><iyz>0</iyz>
          <izz>5e-6</izz>
        </inertia>
      </inertial>
      <collision name="collision">
        <geometry><cylinder><radius>0.025</radius><length>0.03</length></cylinder></geometry>
        <surface><friction><ode><mu>0.8</mu><mu2>0.8</mu2></ode></friction></surface>
      </collision>
      <visual name="visual">
        <geometry><cylinder><radius>0.025</radius><length>0.03</length></cylinder></geometry>
        <material><ambient>0.6 0.6 0.6 1</ambient></material>
      </visual>
    </link>

    <joint name="roller_front_joint" type="revolute">
      <parent>base_link</parent>
      <child>roller_front_link</child>
      <axis>
        <xyz>0 1 0</xyz>
        <limit><lower>-1e16</lower><upper>1e16</upper></limit>
        <dynamics><damping>0.01</damping><friction>0.001</friction></dynamics>
      </axis>
      <pose>0.18 0 -0.10 0 0 0</pose>
    </joint>

    <link name="roller_rear_link">
      <inertial>
        <mass>0.03</mass>
        <inertia>
          <ixx>5e-6</ixx><ixy>0</ixy><ixz>0</ixz>
          <iyy>5e-6</iyy><iyz>0</iyz>
          <izz>5e-6</izz>
        </inertia>
      </inertial>
      <collision name="collision">
        <geometry><cylinder><radius>0.025</radius><length>0.03</length></cylinder></geometry>
        <surface><friction><ode><mu>0.8</mu><mu2>0.8</mu2></ode></friction></surface>
      </collision>
      <visual name="visual">
        <geometry><cylinder><radius>0.025</radius><length>0.03</length></cylinder></geometry>
        <material><ambient>0.6 0.6 0.6 1</ambient></material>
      </visual>
    </link>

    <joint name="roller_rear_joint" type="revolute">
      <parent>base_link</parent>
      <child>roller_rear_link</child>
      <axis>
        <xyz>0 1 0</xyz>
        <limit><lower>-1e16</lower><upper>1e16</upper></limit>
        <dynamics><damping>0.01</damping><friction>0.001</friction></dynamics>
      </axis>
      <pose>-0.18 0 -0.10 0 0 0</pose>
    </joint>

    <!-- ===== LIDAR 支架 ===== -->
    <link name="lidar_link">
      <inertial>
        <mass>0.01</mass>
        <inertia>
          <ixx>1e-6</ixx>
          <ixy>0</ixy>
          <ixz>0</ixz>
          <iyy>1e-6</iyy>
          <iyz>0</iyz>
          <izz>1e-6</izz>
        </inertia>
      </inertial>
      <collision name="collision">
        <geometry>
          <cylinder>
            <radius>0.04</radius>
            <length>0.03</length>
          </cylinder>
        </geometry>
      </collision>
      <visual name="visual">
        <geometry>
          <cylinder>
            <radius>0.04</radius>
            <length>0.03</length>
          </cylinder>
        </geometry>
        <material>
          <ambient>1 0 0 1</ambient>
          <diffuse>1 0 0 1</diffuse>
        </material>
      </visual>

      <!-- ===== 2D 激光扫描仪传感器 ===== -->
      <sensor name="lidar_sensor" type="ray">
        <pose>0 0 0 0 0 0</pose>
        <always_on>1</always_on>
        <visualize>true</visualize>
        <update_rate>10</update_rate>
        <ray>
          <scan>
            <horizontal>
              <samples>360</samples>
              <resolution>1</resolution>
              <min_angle>-3.14159</min_angle>
              <max_angle>3.14159</max_angle>
            </horizontal>
          </scan>
          <range>
            <min>0.12</min>
            <max>10.0</max>
            <resolution>0.01</resolution>
          </range>
          <noise>
            <type>gaussian</type>
            <mean>0.0</mean>
            <stddev>0.01</stddev>
          </noise>
        </ray>
        <plugin name="gpu_lidar_plugin" filename="libgazebo_ros_ray_sensor.so">
          <ros>
            <namespace>robot</namespace>
            <argument>~/out:=scan</argument>
          </ros>
          <output_type>sensor_msgs/LaserScan</output_type>
          <frame_name>lidar_link</frame_name>
        </plugin>
      </sensor>
    </link>

    <joint name="lidar_joint" type="fixed">
      <parent>base_link</parent>
      <child>lidar_link</child>
      <pose>0 0 0.12 0 0 0</pose>
    </joint>

    <!-- ===== IMU 传感器 ===== -->
    <link name="imu_link">
      <inertial>
        <mass>0.001</mass>
        <inertia>
          <ixx>1e-6</ixx><ixy>0</ixy><ixz>0</ixz>
          <iyy>1e-6</iyy><iyz>0</iyz>
          <izz>1e-6</izz>
        </inertia>
      </inertial>
      <sensor name="imu_sensor" type="imu">
        <always_on>1</always_on>
        <update_rate>200</update_rate>
        <imu>
          <angular_velocity>
            <x>
              <noise type="gaussian">
                <mean>0.0</mean>
                <stddev>0.00017</stddev>
              </noise>
            </x>
            <y>
              <noise type="gaussian">
                <mean>0.0</mean>
                <stddev>0.00017</stddev>
              </noise>
            </y>
            <z>
              <noise type="gaussian">
                <mean>0.0</mean>
                <stddev>0.00017</stddev>
              </noise>
            </z>
          </angular_velocity>
          <linear_acceleration>
            <x>
              <noise type="gaussian">
                <mean>0.0</mean>
                <stddev>0.001</stddev>
              </noise>
            </x>
            <y>
              <noise type="gaussian">
                <mean>0.0</mean>
                <stddev>0.001</stddev>
              </noise>
            </y>
            <z>
              <noise type="gaussian">
                <mean>0.0</mean>
                <stddev>0.001</stddev>
              </noise>
            </z>
          </linear_acceleration>
        </imu>
        <plugin name="imu_plugin" filename="libgazebo_ros_imu_sensor.so">
          <ros>
            <namespace>robot</namespace>
          </ros>
          <frame_name>imu_link</frame_name>
        </plugin>
      </sensor>
    </link>

    <joint name="imu_joint" type="fixed">
      <parent>base_link</parent>
      <child>imu_link</child>
      <pose>0 0 0.05 0 0 0</pose>
    </joint>

    <!-- ===== 摄像头传感器 ===== -->
    <link name="camera_link">
      <inertial>
        <mass>0.005</mass>
        <inertia>
          <ixx>1e-6</ixx><ixy>0</ixy><ixz>0</ixz>
          <iyy>1e-6</iyy><iyz>0</iyz>
          <izz>1e-6</izz>
        </inertia>
      </inertial>
      <collision name="collision">
        <geometry>
          <box><size>0.02 0.04 0.02</size></box>
        </geometry>
      </collision>
      <visual name="visual">
        <geometry>
          <box><size>0.02 0.04 0.02</size></box>
        </geometry>
        <material>
          <ambient>0 1 0 1</ambient>
          <diffuse>0 1 0 1</diffuse>
        </material>
      </visual>
      <sensor name="camera_sensor" type="camera">
        <always_on>1</always_on>
        <update_rate>30</update_rate>
        <visualize>false</visualize>
        <camera>
          <horizontal_fov>1.047</horizontal_fov>
          <image>
            <width>640</width>
            <height>480</height>
            <format>R8G8B8</format>
          </image>
          <clip>
            <near>0.1</near>
            <far>100</far>
          </clip>
          <noise>
            <type>gaussian</type>
            <mean>0.0</mean>
            <stddev>0.007</stddev>
          </noise>
        </camera>
        <plugin name="camera_plugin" filename="libgazebo_ros_camera.so">
          <ros>
            <namespace>robot</namespace>
          </ros>
          <frame_name>camera_link</frame_name>
        </plugin>
      </sensor>
    </link>

    <joint name="camera_joint" type="fixed">
      <parent>base_link</parent>
      <child>camera_link</child>
      <pose>0.18 0 0.08 0 0 0</pose>
    </joint>

    <!-- ===== Gazebo ROS 差分驱动插件 ===== -->
    <plugin name="diff_drive" filename="libgazebo_ros_diff_drive.so">
      <ros>
        <namespace>robot</namespace>
      </ros>
      <update_rate>30</update_rate>
      <left_joint>wheel_left_joint</left_joint>
      <right_joint>wheel_right_joint</right_joint>
      <wheel_separation>0.36</wheel_separation>
      <wheel_diameter>0.10</wheel_diameter>
      <max_wheel_torque>5.0</max_wheel_torque>
      <max_wheel_acceleration>0.5</max_wheel_acceleration>
      <command_topic>cmd_vel</command_topic>
      <odometry_topic>odom</odometry_topic>
      <odometry_frame>odom</odometry_frame>
      <robot_base_frame>base_footprint</robot_base_frame>
      <publish_odom_tf>true</publish_odom_tf>
      <publish_wheel_tf>false</publish_wheel_tf>
      <publishTf>1</publishTf>
    </plugin>

    <!-- ===== 关节状态发布插件 ===== -->
    <plugin name="joint_state_publisher"
            filename="libgazebo_ros_joint_state_publisher.so">
      <ros>
        <namespace>robot</namespace>
      </ros>
      <update_rate>30</update_rate>
      <joint_name>wheel_left_joint</joint_name>
      <joint_name>wheel_right_joint</joint_name>
    </plugin>

  </model>
</sdf>
